<?xml version="1.0" ?>
<robot name="aaly" xmlns:xacro="http://ros.org/wiki/xacro">

  <joint name="fixed" type="floating">
      <parent link="world"/>
      <child link="aaly__base_link"/>
  </joint>

  <joint name="aaly__j1" type="revolute">
    <parent link="aaly__base_link"/>
    <child link="aaly__motor1"/>
    <origin rpy="0 0 0" xyz="-0.107 0.0 0.12427"/>
    <axis xyz="1 0 0"/>

    <limit effort="1.5" velocity="1" lower="0" upper="5.235987755982989"/>

    <dynamics damping="5" friction="0.1"/>
  </joint>

  <joint name="aaly__Left_Track_Side_joint" type="fixed">
    <parent link="aaly__base_link"/>
    <child link="aaly__Left_Side_Track_Support"/>
    <origin rpy="0 0 0" xyz="-0.01373 -0.15812 0.06562"/>
    <axis xyz="0 0 0"/>
    <limit effort="0" lower="0" upper="0" velocity="0"/>
  </joint>

  <joint name="aaly__Right_Track_Side_joint" type="fixed">
    <parent link="aaly__base_link"/>
    <child link="aaly__Right_Side_Track_Support"/>
    <origin rpy="0 0 0" xyz="-0.01373 0.15812 0.07062"/>
    <axis xyz="0 0 0"/>
    <limit effort="0" lower="0" upper="0" velocity="0"/>
  </joint>

  <joint name="aaly__drum_joint1" type="continuous">
    <parent link="aaly__Left_Side_Track_Support"/>
    <child link="aaly__drum1"/>
    <origin rpy="1.57079632679 0 0" xyz="-0.1228385 -0.19612 0.030"/>
    <axis xyz="0 1 0"/>
  </joint>

  <joint name="aaly__drum_joint2" type="continuous">
    <parent link="aaly__Right_Side_Track_Support"/>
    <child link="aaly__drum2"/>
    <origin rpy="1.57079632679 0 0" xyz="-0.1228385 0.19612 0.030"/>
    <axis xyz="0 1 0"/>
    <limit effort="0" lower="-1e+16" upper="1e+16" velocity="2"/>
  </joint>

  <joint name="aaly__drum_joint3" type="continuous">
    <parent link="aaly__Left_Side_Track_Support"/>
    <child link="aaly__drum3"/>
    <origin rpy="1.57079632679 0 0" xyz="0.1248385 -0.19612 0.037625"/>
    <axis xyz="0 1 0"/>
    <limit effort="0" lower="-1e+16" upper="1e+16" velocity="2"/>
  </joint>

  <joint name="aaly__drum_joint4" type="continuous">
    <parent link="aaly__Right_Side_Track_Support"/>
    <child link="aaly__drum4"/>
    <origin rpy="1.57079632679 0 0" xyz="0.1248385 0.19612 0.037625"/>
    <axis xyz="0 1 0"/>
    <limit effort="0" lower="-1e+16" upper="1e+16" velocity="2"/>
  </joint>

  <joint name="aaly__drum_joint5" type="continuous">
    <parent link="aaly__Left_Side_Track_Support"/>
    <child link="aaly__drum5"/>
    <origin rpy="1.57079632679 0 0" xyz="-0.0460507 -0.19612 0.154342"/>
    <axis xyz="0 1 0"/>
    <limit effort="0" lower="-1e+16" upper="1e+16" velocity="2"/>
  </joint>

  <joint name="aaly__drum_joint6" type="continuous">
    <parent link="aaly__Right_Side_Track_Support"/>
    <child link="aaly__drum6"/>
    <origin rpy="1.57079632679 0 0" xyz="-0.0460507 0.19612 0.154342"/>
    <axis xyz="0 1 0"/>
    <limit effort="0" lower="-1e+16" upper="1e+16" velocity="2"/>
  </joint>

  <joint name="aaly__Left_Side_Track_Cover_joint" type="fixed">
    <parent link="aaly__Left_Side_Track_Support"/>
    <child link="aaly__Left_Side_Track_Cover"/>
    <origin rpy="0 0 0" xyz="-0.0134385 -0.23112 0.061125"/>
    <axis xyz="0 0 0"/>
    <limit effort="0" lower="0" upper="0" velocity="0"/>
  </joint>

  <joint name="aaly__Right_Side_Track_Cover_joint" type="fixed">
    <parent link="aaly__Right_Side_Track_Support"/>
    <child link="aaly__Right_Side_Track_Cover"/>
    <origin rpy="0 0 0" xyz="-0.0134385 0.23112 0.061125"/>
    <axis xyz="0 0 0"/>
    <limit effort="0" lower="0" upper="0" velocity="0"/>
  </joint>

  <!-- Used for fixing robot to Gazebo 'base_link' -->
  <link name="world"/>

  <link name="aaly__base_link">
    <inertial>
      <mass value="0.36"/>
      <origin rpy="0 0 0" xyz="0 0 0"/>
      <inertia ixx="0.0028086383999999997" ixy="0.0" ixz="0.0" iyy="4.3094400000000005e-05" iyz="0.0" izz="0.0028086383999999997"/>
    </inertial>
    <collision name="aaly__base_link_collision">
      <origin rpy="0 0 0" xyz="-0.07 0 0.12427"/>
      <geometry>
        <box size="0.026988 0.3000 0.026988"/>
      </geometry>
    </collision>
    <visual name="aaly__base_link_visual">
      <origin rpy="0 0 0" xyz="-0.07 0 0.12427"/>
      <geometry>
        <mesh filename="package://aaly_urdf/meshes/Horizontal_Support_Bar_ASB-512.dae" scale="1.0 1.0 1.0"/>
      </geometry>
    </visual>
  </link>

  <link name="aaly__motor1">
    <inertial>
        <mass value="0.05" />
        <inertia ixx="0.04" ixy="0.0" ixz="0.0" iyy="0.04" iyz="0.0" izz="0.04"/>
    </inertial>
    <collision name="aaly__motor1_collision">
      <origin rpy="0 0 0" xyz="0 0 0"/>
      <geometry>
        <box size="0.04 0.032 0.050"/>
      </geometry>
    </collision>
    <visual name="aaly__motor1_visual">
      <origin rpy="0 0 0" xyz="0 0 0"/>
      <geometry>
        <mesh filename="package://aaly_urdf/meshes/AX12-A_origin_same_as_center_of_mass.stl" scale="1.0 1.0 1.0"/>
      </geometry>
    </visual>
  </link>

  <link name="aaly__Left_Side_Track_Support">
    <inertial>
      <mass value="0.01"/>
      <origin rpy="0 0 0" xyz="0 0 0"/>
      <inertia ixx="0.001" ixy="0" ixz="0" iyy="0.001" iyz="0" izz="0.001"/>
    </inertial>
    <collision name="aaly__Left_Side_Track_Support_collision">
      <origin rpy="0 0 0" xyz="0 0 0.015"/>
      <geometry>
        <mesh filename="package://aaly_urdf/meshes/Track_Support_Collision_Mesh.dae" scale="1.0 1.0 1.0"/>
      </geometry>
    </collision>
    <visual name="aaly__Left_Side_Track_Support_visual">
      <origin rpy="0 0 0" xyz="0 0 0"/>
      <geometry>
        <mesh filename="package://aaly_urdf/meshes/Track_Support_Left_Side.dae" scale="1.0 1.0 1.0"/>
      </geometry>
    </visual>
  </link>

  <link name="aaly__Right_Side_Track_Support">
    <inertial>
      <mass value="0.01"/>
      <origin rpy="0 0 0" xyz="0 0 0"/>
      <inertia ixx="0.001" ixy="0" ixz="0" iyy="0.001" iyz="0" izz="0.001"/>
    </inertial>
    <collision name="aaly__Right_Side_Track_Support_collision">
      <origin rpy="0 0 0" xyz="0 0 0.015"/>
      <geometry>
        <mesh filename="package://aaly_urdf/meshes/Track_Support_Collision_Mesh.dae" scale="1.0 1.0 1.0"/>
      </geometry>
    </collision>
    <visual name="aaly__Left_Side_Track_Support_visual">
      <origin rpy="0 0 0" xyz="0 0 0"/>
      <geometry>
        <mesh filename="package://aaly_urdf/meshes/Track_Support_Right_Side.dae" scale="1.0 1.0 1.0"/>
      </geometry>
    </visual>
  </link>

  <link name="aaly__drum1">
    <inertial>
      <mass value="0.1"/>
      <origin rpy="0 0 0" xyz="0 0 0"/>
      <inertia ixx="4.0003370625000006e-05" ixy="0.0" ixz="0.0" iyy="4.0003370625000006e-05" iyz="0.0" izz="3.624778125000001e-05"/>
    </inertial>
    <collision name="aaly__drum1_collision">
      <origin rpy="0 0 0" xyz="0 0 0"/>
      <geometry>
        <cylinder length="0.05124" radius="0.026925"/>
      </geometry>
    </collision>
    <visual name="aaly__drum1_visual">
      <origin rpy="0 0 0" xyz="0 0 0"/>
      <geometry>
        <mesh filename="package://aaly_urdf/meshes/Lynx_Sproket6in_Hub13.dae" scale="1.0 1.0 1.0"/>
      </geometry>
    </visual>
  </link>

  <link name="aaly__drum2">
    <inertial>
      <mass value="0.1"/>
      <origin rpy="0 0 0" xyz="0 0 0"/>
      <inertia ixx="4.0003370625000006e-05" ixy="0.0" ixz="0.0" iyy="4.0003370625000006e-05" iyz="0.0" izz="3.624778125000001e-05"/>
    </inertial>
    <collision name="aaly__drum2_collision">
      <origin rpy="0 0 0" xyz="0 0 0"/>
      <geometry>
        <cylinder length="0.05124" radius="0.026525"/>
      </geometry>
    </collision>
    <visual name="aaly__drum2_visual">
      <origin rpy="0 0 0" xyz="0 0 0"/>
      <geometry>
        <mesh filename="package://aaly_urdf/meshes/Lynx_Sproket6in_Hub13.dae" scale="1.0 1.0 1.0"/>
      </geometry>
    </visual>
  </link>

  <link name="aaly__drum3">
    <inertial>
      <mass value="0.15"/>
      <origin rpy="0 0 0" xyz="0 0 0"/>
      <inertia ixx="5.5414245624999996e-05" ixy="0.0" ixz="0.0" iyy="5.5414245624999996e-05" iyz="0.0" izz="0.000100604296875"/>
    </inertial>
    <collision name="aaly__drum3_collision">
      <origin rpy="0 0 0" xyz="0 0 0"/>
      <geometry>
        <cylinder length="0.05124" radius="0.035625"/>
      </geometry>
    </collision>
    <visual name="aaly__drum3_visual">
      <origin rpy="0 0 0" xyz="0 0 0"/>
      <geometry>
        <mesh filename="package://aaly_urdf/meshes/Lynx_Sproket9in_Hub13.dae" scale="1.0 1.0 1.0"/>
      </geometry>
    </visual>
  </link>

  <link name="aaly__drum4">
    <inertial>
      <mass value="0.15"/>
      <origin rpy="0 0 0" xyz="0 0 0"/>
      <inertia ixx="5.5414245624999996e-05" ixy="0.0" ixz="0.0" iyy="5.5414245624999996e-05" iyz="0.0" izz="0.000100604296875"/>
    </inertial>
    <collision name="aaly__drum4_collision">
      <origin rpy="0 0 0" xyz="0 0 0"/>
      <geometry>
        <cylinder length="0.05124" radius="0.035625"/>
      </geometry>
    </collision>
    <visual name="aaly__drum4_visual">
      <origin rpy="0 0 0" xyz="0 0 0"/>
      <geometry>
        <mesh filename="package://aaly_urdf/meshes/Lynx_Sproket9in_Hub13.dae" scale="1.0 1.0 1.0"/>
      </geometry>
    </visual>
  </link>

  <link name="aaly__drum5">
    <inertial>
      <mass value="0.1"/>
      <origin rpy="0 0 0" xyz="0 0 0"/>
      <inertia ixx="4.0003370625000006e-05" ixy="0.0" ixz="0.0" iyy="4.0003370625000006e-05" iyz="0.0" izz="3.624778125000001e-05"/>
    </inertial>
    <collision name="aaly__drum5_collision">
      <origin rpy="0 0 0" xyz="0 0 0"/>
      <geometry>
        <cylinder length="0.05124" radius="0.026525"/>
      </geometry>
    </collision>
    <visual name="aaly__drum5_visual">
      <origin rpy="0 0 0" xyz="0 0 0"/>
      <geometry>
        <mesh filename="package://aaly_urdf/meshes/Lynx_Sproket6in_Hub13.dae" scale="1.0 1.0 1.0"/>
      </geometry>
    </visual>
  </link>

  <link name="aaly__drum6">
    <inertial>
      <mass value="0.1"/>
      <origin rpy="0 0 0" xyz="0 0 0"/>
      <inertia ixx="4.0003370625000006e-05" ixy="0.0" ixz="0.0" iyy="4.0003370625000006e-05" iyz="0.0" izz="3.624778125000001e-05"/>
    </inertial>
    <collision name="aaly__drum6_collision">
      <origin rpy="0 0 0" xyz="0 0 0"/>
      <geometry>
        <cylinder length="0.05124" radius="0.026525"/>
      </geometry>
    </collision>
    <visual name="aaly__drum6_visual">
      <origin rpy="0 0 0" xyz="0 0 0"/>
      <geometry>
        <mesh filename="package://aaly_urdf/meshes/Lynx_Sproket6in_Hub13.dae" scale="1.0 1.0 1.0"/>
      </geometry>
    </visual>
  </link>

  <link name="aaly__Left_Side_Track_Cover">
    <inertial>
      <mass value="0.01"/>
      <origin rpy="0 0 0" xyz="0 0 0"/>
      <inertia ixx="0.001" ixy="0" ixz="0" iyy="0.001" iyz="0" izz="0.001"/>
    </inertial>
    <collision name="aaly__Left_Side_Track_Cover_collision">
      <origin rpy="0 0 0" xyz="0 0 0.015"/>
      <geometry>
        <mesh filename="package://aaly_urdf/meshes/Track_Support_Collision_Mesh.dae" scale="1.0 1.0 1.0"/>
      </geometry>
    </collision>
    <visual name="aaly__Left_Side_Track_Cover_visual">
      <origin rpy="0 0 0" xyz="0 0 0"/>
      <geometry>
        <mesh filename="package://aaly_urdf/meshes/Track_Support_Cover_Side.dae" scale="1.0 1.0 1.0"/>
      </geometry>
    </visual>
  </link>

  <link name="aaly__Right_Side_Track_Cover">
    <inertial>
      <mass value="0.01"/>
      <origin rpy="0 0 0" xyz="0 0 0"/>
      <inertia ixx="0.001" ixy="0" ixz="0" iyy="0.001" iyz="0" izz="0.001"/>
    </inertial>
    <collision name="aaly__Right_Side_Track_Cover_collision">
      <origin rpy="0 0 0" xyz="0 0 0.015"/>
      <geometry>
        <mesh filename="package://aaly_urdf/meshes/Track_Support_Collision_Mesh.dae" scale="1.0 1.0 1.0"/>
      </geometry>
    </collision>
    <visual name="aaly__Right_Side_Track_Cover_visual">
      <origin rpy="0 0 0" xyz="0 0 0"/>
      <geometry>
        <mesh filename="package://aaly_urdf/meshes/Track_Support_Cover_Side.dae" scale="1.0 1.0 1.0"/>
      </geometry>
    </visual>
  </link>



    <!-- Replaced Gazebo's differential drive plugin with the
         ROS-friendly variant -->
    <gazebo>
      <plugin name="gazebo_ros_control" filename="libgazebo_ros_control.so">
        <robotNamespace>/aaly_robot</robotNamespace>
      </plugin>
    </gazebo>


  <transmission name="tran1">
    <type>transmission_interface/SimpleTransmission</type>
    <joint name="aaly__j1">
      <hardwareInterface>hardware_interface/PositionJointInterface</hardwareInterface>
    </joint>
    <actuator name="aaly__motor1">
      <hardwareInterface>hardware_interface/PositionJointInterface</hardwareInterface>
      <mechanicalReduction>1</mechanicalReduction>
    </actuator>
  </transmission>

  <transmission name="left_wheel_transmission">
  <type>transmission_interface/SimpleTransmission</type>
  <joint name="aaly__drum_joint5">
    <hardwareInterface>hardware_interface/VelocityJointInterface</hardwareInterface>  
  </joint>
  <actuator name="aaly__drum5">
    <mechanicalReduction>1</mechanicalReduction>
    <hardwareInterface>VelocityJointInterface</hardwareInterface>
  </actuator>
</transmission>
 
<transmission name="right_wheel_transmission">
  <type>transmission_interface/SimpleTransmission</type>
  <joint name="aaly__drum_joint6">
    <hardwareInterface>hardware_interface/VelocityJointInterface</hardwareInterface>  
  </joint>
  <actuator name="aaly__drum6">
    <mechanicalReduction>1</mechanicalReduction>
    <hardwareInterface>VelocityJointInterface</hardwareInterface>
  </actuator>
</transmission>

</robot>
