<sdf version="1.4">
  <model name="track_creator">
    <link name="base_link">
      <self_collide>0</self_collide>
      <pose>-0.07 0 0.1242752 0 0 0</pose>
      <inertial>
        <mass>0.36</mass>
        <inertia> 
          <ixx>0.0028086383999999997</ixx> 
          <ixy>0.0</ixy>
          <ixz>0.0</ixz>
          <iyy>4.3094400000000005e-05</iyy>
          <iyz>0.0</iyz>
          <izz>0.0028086383999999997</izz>
        </inertia>
      </inertial>
      <collision name="base_link_collision">
        <geometry>
          <box>
            <size>0.026988 0.3000 0.026988</size>
          </box>
        </geometry>
      </collision>
      <visual name="base_link_visual">
        <geometry>
          <mesh>
            <uri>model://my_tracks/meshes/Horizontal_Support_Bar_ASB-512.dae</uri>
          </mesh>
        </geometry>
      </visual>
    </link>

    <!--Lower Right and left legs-->
    <link name="motor1">
      <self_collide>1</self_collide>
      <pose>-0.107 0 0.1242752 0 0 0</pose>
      <inertial>        
        <mass>0.055</mass>
        <inertia> 
          <ixx>1.8791666666e-05</ixx> 
          <ixy>0.0</ixy>
          <ixz>0.0</ixz>
          <iyy>1.7086666666e-05</iyy>
          <iyz>0.0</iyz>
          <izz>1.2026666666e-05</izz>
        </inertia>
      </inertial>
      <collision name="motor1_collision">
        <geometry>
          <box>
            <size>0.04 0.032 0.050</size>
          </box>
        </geometry>
      </collision>
      <visual name="motor1_visual">
        <geometry>
          <mesh> 
            <uri>model://my_tracks/meshes/AX12-A_origin_same_as_center_of_mass.stl</uri>
          </mesh>
        </geometry>
      </visual>
    </link>

    <joint name="j1" type="revolute">
      <pose>0 0 0 0 0 0</pose>
      <parent>base_link</parent>
      <child>motor1</child>
      <axis> 
        <xyz>1 0 0</xyz>
      </axis>
    </joint>



    <link name="Left_Side_Track_Support">
      <self_collide>1</self_collide>
      <pose>-0.0137385 -0.15812 0.065625 0 0 0</pose>
      <collision name="Left_Side_Track_Support_collision">
        <pose>0 0 0.015 0 0 0</pose>
        <geometry>
          <mesh>
            <uri>model://my_tracks/meshes/Track_Support_Collision_Mesh.dae</uri>
          </mesh>
        </geometry>
      </collision>
      <visual name="Left_Side_Track_Support_visual">
        <geometry>
          <mesh>
            <uri>model://my_tracks/meshes/Track_Support_Left_Side.dae</uri>
          </mesh>
        </geometry>
      </visual>
    </link>
    <joint name="Left_Track_Side_joint" type="fixed">
      <pose>0 0 0 0 0 0</pose>
      <parent>base_link</parent>
      <child>Left_Side_Track_Support</child>
      <axis>
        <xyz>0 0 0</xyz>
      </axis>
    </joint>

    <link name="Right_Side_Track_Support">
      <self_collide>1</self_collide>
      <pose>-0.0137385 0.15812 0.070625 0 0 0</pose>
      <collision name="Right_Side_Track_Support_collision">
        <pose>0 0 0.015 0 0 0</pose>
        <geometry>
          <mesh>
            <uri>model://my_tracks/meshes/Track_Support_Collision_Mesh.dae</uri>
          </mesh>
        </geometry>
      </collision>
      <visual name="Left_Side_Track_Support_visual">
        <geometry>
          <mesh>
            <uri>model://my_tracks/meshes/Track_Support_Right_Side.dae</uri>
          </mesh>
        </geometry>
      </visual>
    </link>
    <joint name="Right_Track_Side_joint" type="fixed">
      <pose>0 0 0 0 0 0</pose>
      <parent>base_link</parent>
      <child>Right_Side_Track_Support</child>
      <axis>
        <xyz>0 0 0</xyz>
      </axis>
    </joint>


    <link name="drum1">
      <self_collide>1</self_collide>
      <pose>-0.1228385 -0.19612 0.030 1.57079632679 0 0</pose>
      <inertial>        
        <mass>0.1</mass>
        <inertia> 
          <ixx>4.0003370625000006e-05</ixx> 
          <ixy>0.0</ixy>
          <ixz>0.0</ixz>
          <iyy>4.0003370625000006e-05</iyy>
          <iyz>0.0</iyz>
          <izz>3.624778125000001e-05</izz>
        </inertia>
      </inertial>
      <collision name="drum1_collision">
        <geometry>
          <cylinder>
            <radius>0.026525</radius>
            <length>0.05124</length>
          </cylinder>
        </geometry>
      </collision>
      <visual name="drum1_visual">
        <geometry>
          <mesh>
            <uri>model://my_tracks/meshes/Lynx_Sproket6in_Hub13.dae</uri>
          </mesh>
        </geometry>
      </visual>
    </link>
    <joint name="drum_joint1" type="revolute">
      <pose>0 0 0 0 0 0</pose>
      <parent>Left_Side_Track_Support</parent>
      <child>drum1</child>
      <axis>
        <xyz>0 1 0</xyz>
      </axis>
    </joint>

    <link name="drum2">
      <self_collide>1</self_collide>
      <pose>-0.1228385 0.19612 0.030 1.57079632679 0 0</pose>
      <inertial>
        <mass>0.1</mass>
        <inertia> 
          <ixx>4.0003370625000006e-05</ixx> 
          <ixy>0.0</ixy>
          <ixz>0.0</ixz>
          <iyy>4.0003370625000006e-05</iyy>
          <iyz>0.0</iyz>
          <izz>3.624778125000001e-05</izz>
        </inertia>
      </inertial>
      <collision name="drum2_collision">
        <geometry>
          <cylinder>
            <radius>0.026525</radius>
            <length>0.05124</length>
          </cylinder>
        </geometry>
      </collision>
      <visual name="drum2_visual">
        <geometry>
          <mesh>
            <uri>model://my_tracks/meshes/Lynx_Sproket6in_Hub13.dae</uri>
          </mesh>
        </geometry>
      </visual>
    </link>
    <joint name="drum_joint2" type="revolute">
      <pose>0 0 0 0 0 0</pose>
      <parent>Right_Side_Track_Support</parent>
      <child>drum2</child>
      <axis>
        <xyz>0 1 0</xyz>
      </axis>
    </joint>
    <link name="drum3">
      <self_collide>1</self_collide>
      <pose>0.1248385 -0.19612 0.037625 1.57079632679 0 0</pose>
      <inertial>
        <mass>0.15</mass>
        <inertia> 
          <ixx>5.5414245624999996e-05</ixx> 
          <ixy>0.0</ixy>
          <ixz>0.0</ixz>
          <iyy>5.5414245624999996e-05</iyy>
          <iyz>0.0</iyz>
          <izz>0.000100604296875</izz>
        </inertia>
      </inertial>
      <collision name="drum3_collision">
        <geometry>
          <cylinder>
            <radius>0.035625</radius>
            <length>0.05124</length>
          </cylinder>
        </geometry>
      </collision>
      <visual name="drum3_visual">
        <geometry>
          <mesh>
            <uri>model://my_tracks/meshes/Lynx_Sproket9in_Hub13.dae</uri>
          </mesh>
        </geometry>
      </visual>
    </link>
    <joint name="drum_joint3" type="revolute">
      <pose>0 0 0 0 0 0</pose>
      <parent>Left_Side_Track_Support</parent>
      <child>drum3</child>
      <axis>
        <xyz>0 1 0</xyz>
      </axis>
    </joint>
    <link name="drum4">
      <self_collide>1</self_collide>
      <pose>0.1248385 0.19612 0.037625 1.57079632679 0 0</pose>
      <inertial>
        <mass>0.15</mass>
        <inertia> 
          <ixx>5.5414245624999996e-05</ixx> 
          <ixy>0.0</ixy>
          <ixz>0.0</ixz>
          <iyy>5.5414245624999996e-05</iyy>
          <iyz>0.0</iyz>
          <izz>0.000100604296875</izz>
        </inertia>
      </inertial>
      <collision name="drum4_collision">
        <geometry>
          <cylinder>
            <radius>0.035625</radius>
            <length>0.05124</length>
          </cylinder>
        </geometry>
      </collision>
      <visual name="drum4_visual">
        <geometry>
          <mesh>
            <uri>model://my_tracks/meshes/Lynx_Sproket9in_Hub13.dae</uri>
          </mesh>
        </geometry>
      </visual>
    </link>
    <joint name="drum_joint4" type="revolute">
      <pose>0 0 0 0 0 0</pose>
      <parent>Right_Side_Track_Support</parent>
      <child>drum4</child>
      <axis>
        <xyz>0 1 0</xyz>
      </axis>
    </joint>
    <link name="drum5">
      <self_collide>1</self_collide>
      <pose>-0.0460507 -0.19612 0.154342 1.57079632679 0 0</pose>
      <inertial>
        <mass>0.1</mass>
        <inertia> 
          <ixx>4.0003370625000006e-05</ixx> 
          <ixy>0.0</ixy>
          <ixz>0.0</ixz>
          <iyy>4.0003370625000006e-05</iyy>
          <iyz>0.0</iyz>
          <izz>3.624778125000001e-05</izz>
        </inertia>
      </inertial>
      <collision name="drum5_collision">
        <geometry>
          <cylinder>
            <radius>0.026525</radius>
            <length>0.05124</length>
          </cylinder>
        </geometry>
        <surface>
          <friction>
            <ode>
              <mu>1.50</mu>
              <mu2>1.50</mu2>
            </ode>
          </friction>
        </surface>
      </collision>
      <visual name="drum5_visual">
        <geometry>
          <mesh>
            <uri>model://my_tracks/meshes/Lynx_Sproket6in_Hub13.dae</uri>
          </mesh>
        </geometry>
      </visual>
    </link>
    <joint name="drum_joint5" type="revolute">
      <pose>0 0 0 0 0 0</pose>
      <parent>Left_Side_Track_Support</parent>
      <child>drum5</child>
      <axis>
        <xyz>0 1 0</xyz>
      </axis>
    </joint>
    <link name="drum6">
      <self_collide>1</self_collide>
      <pose>-0.0460507 0.19612 0.154342 1.57079632679 0 0</pose>
      <inertial>
        <mass>0.1</mass>
        <inertia> 
          <ixx>4.0003370625000006e-05</ixx> 
          <ixy>0.0</ixy>
          <ixz>0.0</ixz>
          <iyy>4.0003370625000006e-05</iyy>
          <iyz>0.0</iyz>
          <izz>3.624778125000001e-05</izz>
        </inertia>
      </inertial>
      <collision name="drum6_collision">
        <geometry>
          <cylinder>
            <radius>0.026525</radius>
            <length>0.05124</length>
          </cylinder>
        </geometry>
        <surface>
          <friction>
            <ode>
              <mu>1.51</mu>
              <mu2>1.51</mu2>
            </ode>
          </friction>
        </surface>
      </collision>
      <visual name="drum6_visual">
        <geometry>
          <mesh>
            <uri>model://my_tracks/meshes/Lynx_Sproket6in_Hub13.dae</uri>
          </mesh>
        </geometry>
      </visual>
    </link>
    <joint name="drum_joint6" type="revolute">
      <pose>0 0 0 0 0 0</pose>
      <parent>Right_Side_Track_Support</parent>
      <child>drum6</child>
      <axis>
        <xyz>0 1 0</xyz>
      </axis>
    </joint>




    <link name="Left_Side_Track_Cover">
      <self_collide>1</self_collide>
      <pose>-0.0134385 -0.23112 0.061125 0 0 0</pose>
      <collision name="Left_Side_Track_Cover_collision">
        <pose>0 0 0.015 0 0 0</pose>
        <geometry>
          <mesh>
            <uri>model://my_tracks/meshes/Track_Support_Collision_Mesh.dae</uri>
          </mesh>
        </geometry>
      </collision>
      <visual name="Left_Side_Track_Cover_visual">
        <geometry>
          <mesh>
            <uri>model://my_tracks/meshes/Track_Support_Cover_Side.dae</uri>
          </mesh>
        </geometry>
      </visual>
    </link>
    <joint name="Left_Side_Track_Cover_joint" type="fixed">
      <pose>0 0 0 0 0 0</pose>
      <parent>Left_Side_Track_Support</parent>
      <child>Left_Side_Track_Cover</child>
      <axis>
        <xyz>0 0 0</xyz>
      </axis>
    </joint>



    <link name="Right_Side_Track_Cover">
      <self_collide>1</self_collide>
      <pose>-0.0134385 0.23112 0.061125 0 0 0</pose>
      <collision name="Right_Side_Track_Cover_collision">
        <pose>0 0 0.015 0 0 0</pose>
        <geometry>
          <mesh>
            <uri>model://my_tracks/meshes/Track_Support_Collision_Mesh.dae</uri>
          </mesh>
        </geometry>
      </collision>
      <visual name="Right_Side_Track_Cover_visual">
        <geometry>
          <mesh>
            <uri>model://my_tracks/meshes/Track_Support_Cover_Side.dae</uri>
          </mesh>
        </geometry>
      </visual>
    </link>
    <joint name="Right_Side_Track_Cover_joint" type="fixed">
      <pose>0 0 0 0 0 0</pose>
      <parent>Right_Side_Track_Support</parent>
      <child>Right_Side_Track_Cover</child>
      <axis>
        <xyz>0 0 0</xyz>
      </axis>
    </joint>

  <!-- Gazebo plugin for ROS Control -->

      <plugin name="gazebo_ros_control" filename="libgazebo_ros_control.so">
        <robotNamespace></robotNamespace>
        <robotSimType>gazebo_ros_control/DefaultRobotHWSim</robotSimType>
      </plugin>

  </model>
</sdf>
