<?xml version="1.0" ?>
<robot name="aaly">
  <joint name="aaly__knee_left_back_joint" type="revolute">
    <parent link="aaly__base_link"/>
    <child link="aaly__knee_left_back_motor"/>
    <origin rpy="0  0  0" xyz="-0.107    0.1144   0.12127"/>
    <axis xyz="-1  0  0"/>
    <limit effort="200.0" lower="0.0" upper="5.23598775598" velocity="1.0"/>
  </joint>
  <joint name="aaly__leg_left_back_joint" type="fixed">
    <parent link="aaly__knee_left_back_motor"/>
    <child link="aaly__leg_left_back"/>
    <origin rpy="0  0  0" xyz="-0.0015  -0.0239  -0.05622"/>
    <axis xyz="0  0  0"/>
    <limit effort="0" lower="0" upper="0" velocity="0"/>
  </joint>
  <joint name="aaly__thigh_left_back_motor_joint" type="revolute">
    <parent link="aaly__leg_left_back"/>
    <child link="aaly__thigh_left_back_motor"/>
    <origin rpy="3.14159  0       0" xyz="-0.0015  -0.0395   0.00622"/>
    <axis xyz="1  0  0"/>
    <limit effort="200.0" lower="0.0" upper="5.23598775598" velocity="1.0"/>
  </joint>
  <joint name="aaly__thigh_left_back_joint" type="fixed">
    <parent link="aaly__thigh_left_back_motor"/>
    <child link="aaly__thigh_left_back"/>
    <origin rpy="-3.14159  0      -1.57079" xyz="0       0.001   -0.03322"/>
    <axis xyz="0  0  0"/>
    <limit effort="0" lower="0" upper="0" velocity="0"/>
  </joint>
  <joint name="aaly__knee_left_front_joint" type="revolute">
    <parent link="aaly__base_link"/>
    <child link="aaly__knee_left_front_motor"/>
    <origin rpy="0       0       3.14159" xyz="-0.034    0.1144   0.12127"/>
    <axis xyz="1  0  0"/>
    <limit effort="200.0" lower="0.0" upper="5.23598775598" velocity="1.0"/>
  </joint>
  <joint name="aaly__leg_left_front_joint" type="fixed">
    <parent link="aaly__knee_left_front_motor"/>
    <child link="aaly__leg_left_front"/>
    <origin rpy="0       0      -3.14159" xyz="-0.00376  0.0239  -0.05622"/>
    <axis xyz="0  0  0"/>
    <limit effort="0" lower="0" upper="0" velocity="0"/>
  </joint>
  <joint name="aaly__thigh_left_front_motor_joint" type="revolute">
    <parent link="aaly__leg_left_front"/>
    <child link="aaly__thigh_left_front_motor"/>
    <origin rpy="3.14159  0       3.14159" xyz="-0.00076 -0.0395   0.00622"/>
    <axis xyz="-1  0  0"/>
    <limit effort="200.0" lower="0.0" upper="5.23598775598" velocity="1.0"/>
  </joint>
  <joint name="aaly__thigh_left_joint" type="fixed">
    <parent link="aaly__thigh_left_front_motor"/>
    <child link="aaly__thigh_left_front"/>
    <origin rpy="3.14159  0       1.57079" xyz="0      -0.001   -0.03322"/>
    <axis xyz="0  0  0"/>
    <limit effort="0" lower="0" upper="0" velocity="0"/>
  </joint>
  <joint name="aaly__knee_right_back_joint" type="revolute">
    <parent link="aaly__base_link"/>
    <child link="aaly__knee_right_back_motor"/>
    <origin rpy="0  0  0" xyz="-0.107   -0.1144   0.12127"/>
    <axis xyz="1  0  0"/>
    <limit effort="200.0" lower="0.0" upper="5.23598775598" velocity="1.0"/>
  </joint>
  <joint name="aaly__leg_right_back_joint" type="fixed">
    <parent link="aaly__knee_right_back_motor"/>
    <child link="aaly__leg_right_back"/>
    <origin rpy="0  0  0" xyz="-0.0015   0.0239  -0.05622"/>
    <axis xyz="0  0  0"/>
    <limit effort="0" lower="0" upper="0" velocity="0"/>
  </joint>
  <joint name="aaly__thigh_right_back_motor_joint" type="revolute">
    <parent link="aaly__leg_right_back"/>
    <child link="aaly__thigh_right_back_motor"/>
    <origin rpy="3.14159  0       0" xyz="-0.0015   0.0395   0.00622"/>
    <axis xyz="-1  0  0"/>
    <limit effort="200.0" lower="0.0" upper="5.23598775598" velocity="1.0"/>
  </joint>
  <joint name="aaly__thigh_right_back_joint" type="fixed">
    <parent link="aaly__thigh_right_back_motor"/>
    <child link="aaly__thigh_right_back"/>
    <origin rpy="3.11859  0      -1.57079" xyz="0       0.001   -0.05622"/>
    <axis xyz="0  0  0"/>
    <limit effort="0" lower="0" upper="0" velocity="0"/>
  </joint>
  <joint name="aaly__knee_right_front_joint" type="revolute">
    <parent link="aaly__base_link"/>
    <child link="aaly__knee_right_front_motor"/>
    <origin rpy="0       0       3.14159" xyz="-0.034   -0.1144   0.12127"/>
    <axis xyz="-1  0  0"/>
    <limit effort="200.0" lower="0.0" upper="5.23598775598" velocity="1.0"/>
  </joint>
  <joint name="aaly__leg_right_front_joint" type="fixed">
    <parent link="aaly__knee_right_front_motor"/>
    <child link="aaly__leg_right_front"/>
    <origin rpy="0       0      -3.14159" xyz="-0.00376 -0.0239  -0.05622"/>
    <axis xyz="0  0  0"/>
    <limit effort="0" lower="0" upper="0" velocity="0"/>
  </joint>
  <joint name="aaly__thigh_right_front_motor_joint" type="revolute">
    <parent link="aaly__leg_right_front"/>
    <child link="aaly__thigh_right_front_motor"/>
    <origin rpy="3.14159  0       0" xyz="0.0005   0.0395   0.00622"/>
    <axis xyz="-1  0  0"/>
    <limit effort="200.0" lower="0.0" upper="5.23598775598" velocity="1.0"/>
  </joint>
  <joint name="aaly__thigh_right_joint" type="fixed">
    <parent link="aaly__thigh_right_front_motor"/>
    <child link="aaly__thigh_right_front"/>
    <origin rpy="-3.14159  0      -1.57079" xyz="-0.00025  0.001   -0.03322"/>
    <axis xyz="0  0  0"/>
    <limit effort="0" lower="0" upper="0" velocity="0"/>
  </joint>


  <joint name="aaly__body_front_right_joint" type="revolute">
    <parent link="aaly__thigh_right_front"/>
    <child link="aaly__body1"/>
    <origin rpy="0       0      -1.57079" xyz="0      0      0.0655"/>
    <axis xyz="1  0  0"/>
    <limit effort="200.0" lower="-5.23598775598" upper="5.23598775598" velocity="1.0"/>
  </joint>
  <joint name="aaly__body_back_right_joint" type="revolute">
    <parent link="aaly__thigh_right_back"/>
    <child link="aaly__body2"/>
    <origin rpy="0       0.023   -1.57079" xyz="0      -0.00097  0.04248"/>
    <axis xyz="1  0  0"/>
    <limit effort="200.0" lower="-5.23598775598" upper="5.23598775598" velocity="1.0"/>
  </joint>
  <joint name="aaly__body_front_left_joint" type="revolute">
    <parent link="aaly__thigh_left_front"/>
    <child link="aaly__body3"/>
    <origin rpy="0       0      -1.57079" xyz="0.002  -0.001   0.0655"/>
    <axis xyz="1  0  0"/>
    <limit effort="200.0" lower="-5.23598775598" upper="5.23598775598" velocity="1.0"/>
  </joint>
  <joint name="aaly__body_back_left_joint" type="revolute">
    <parent link="aaly__thigh_left_back"/>
    <child link="aaly__body4"/>
    <origin rpy="0       0      -1.57079" xyz="0.002   0      0.0655"/>
    <axis xyz="1  0  0"/>
    <limit effort="200.0" lower="-5.23598775598" upper="5.23598775598" velocity="1.0"/>
  </joint>

  
  <joint name="aaly__Right_Track_Side_joint" type="fixed">
    <parent link="aaly__base_link"/>
    <child link="aaly__Right_Side_Track_Support"/>
    <origin rpy="0  0  0" xyz="-0.07122 -0.15412  0.12835"/>
    <axis xyz="0  0  0"/>
    <limit effort="0" lower="0" upper="0" velocity="0"/>
  </joint>
  <joint name="aaly__Left_Track_Side_joint" type="fixed">
    <parent link="aaly__base_link"/>
    <child link="aaly__Left_Side_Track_Support"/>
    <origin rpy="0  0  0" xyz="-0.07122  0.15412  0.12835"/>
    <axis xyz="0  0  0"/>
    <limit effort="0" lower="0" upper="0" velocity="0"/>
  </joint>
  <joint name="aaly__drum_joint1" type="continuous">
    <parent link="aaly__Right_Side_Track_Support"/>
    <child link="aaly__drum1"/>
    <origin rpy="1.57079  0       0" xyz="-0.05361 -0.042   -0.09835"/>
    <axis xyz="0  0 -1"/>
  </joint>
  <joint name="aaly__drum_joint2" type="continuous">
    <parent link="aaly__Left_Side_Track_Support"/>
    <child link="aaly__drum2"/>
    <origin rpy="1.57079  0       0" xyz="-0.05361  0.042   -0.09835"/>
    <axis xyz="0  0 -1"/>
  </joint>
  <joint name="aaly__drum_joint3" type="continuous">
    <parent link="aaly__Right_Side_Track_Support"/>
    <child link="aaly__drum3"/>
    <origin rpy="1.57079  0       0" xyz="0.20006 -0.042   -0.09073"/>
    <axis xyz="0  0 -1"/>
  </joint>
  <joint name="aaly__drum_joint4" type="continuous">
    <parent link="aaly__Left_Side_Track_Support"/>
    <child link="aaly__drum4"/>
    <origin rpy="1.57079  0       0" xyz="0.20006  0.042   -0.09073"/>
    <axis xyz="0  0 -1"/>
  </joint>
  <joint name="aaly__drum_joint5" type="continuous">
    <parent link="aaly__Right_Side_Track_Support"/>
    <child link="aaly__drum5"/>
    <origin rpy="1.57079  0       0" xyz="0.02517 -0.042    0.02598"/>
    <axis xyz="0  0 -1"/>
  </joint>
  <joint name="aaly__drum_joint6" type="continuous">
    <parent link="aaly__Left_Side_Track_Support"/>
    <child link="aaly__drum6"/>
    <origin rpy="1.57079  0       0" xyz="0.02517  0.042    0.02598"/>
    <axis xyz="0  0 -1"/>
  </joint>
  <joint name="aaly__Right_Side_Track_Cover_joint" type="fixed">
    <parent link="aaly__Right_Side_Track_Support"/>
    <child link="aaly__Right_Side_Track_Cover"/>
    <origin rpy="0  0  0" xyz="0.05779 -0.077   -0.06673"/>
    <axis xyz="0  0  0"/>
    <limit effort="0" lower="0" upper="0" velocity="0"/>
  </joint>
  <joint name="aaly__Left_Side_Track_Cover_joint" type="fixed">
    <parent link="aaly__Left_Side_Track_Support"/>
    <child link="aaly__Left_Side_Track_Cover"/>
    <origin rpy="0  0  0" xyz="0.05779  0.077   -0.06673"/>
    <axis xyz="0  0  0"/>
    <limit effort="0" lower="0" upper="0" velocity="0"/>
  </joint>
  <link name="aaly__base_link">
    <inertial>
      <mass value="0.36"/>
      <origin rpy="0  0  0" xyz="0  0  0"/>
      <inertia ixx="0.002814604013121458" ixy="0.0" ixz="0.0" iyy="7.17760831593746e-05" iyz="0.0" izz="0.0028301708345758957"/>
    </inertial>
    <collision name="aaly__base_link_collision">
      <origin rpy="0  0  0" xyz="-0.07     0       0.12427"/>
      <geometry>
        <box size="0.026988 0.3000 0.026988"/>
      </geometry>
    </collision>
    <visual name="aaly__base_link_visual">
      <origin rpy="0  0  0" xyz="-0.07     0       0.12427"/>
      <geometry>
        <mesh filename="package://aaly_urdf/meshes/Horizontal_Support_Bar_ASB-512.dae" scale="1.0 1.0 1.0"/>
      </geometry>
    </visual>
  </link>
  <link name="aaly__knee_left_back_motor">
    <inertial>
      <mass value="0.05"/>
      <origin rpy="0  0  0" xyz="0     0    -0.012"/>
      <inertia ixx="1.2166047261762851e-05" ixy="0.0" ixz="0.0" iyy="1.4468363602365426e-05" iyz="0.0" izz="7.993829324731787e-06"/>
    </inertial>
    <collision name="aaly__knee_left_back_motor_collision">
      <origin rpy="0  0  0" xyz="0  0  0"/>
      <geometry>
        <box size="0.04 0.032 0.050"/>
      </geometry>
    </collision>
    <visual name="aaly__knee_left_back_motor_visual">
      <origin rpy="0  0  0" xyz="0  0  0"/>
      <geometry>
        <mesh filename="package://aaly_urdf/meshes/AX12-A_origin_same_as_center_of_mass.stl" scale="1.0 1.0 1.0"/>
      </geometry>
    </visual>
  </link>
  <link name="aaly__leg_left_back">
    <inertial>
      <mass value="0.04"/>
      <origin rpy="0  0  0" xyz="0  0  0"/>
      <inertia ixx="2.69490184257131e-05" ixy="0.0" ixz="0.0" iyy="1.843324918045141e-05" iyz="0.0" izz="3.454538603564566e-05"/>
    </inertial>
    <collision name="aaly__leg_left_back_collision">
      <origin rpy="0  0  0" xyz="0  0  0"/>
      <geometry>
        <box size="0.04 0.04 0.025"/>
      </geometry>
    </collision>
    <visual name="aaly__leg_left_back_visual">
      <origin rpy="0  0  0" xyz="0  0  0"/>
      <geometry>
        <mesh filename="package://aaly_urdf/meshes/Leg_Left_Back.stl" scale="1.0 1.0 1.0"/>
      </geometry>
    </visual>
  </link>
  <link name="aaly__thigh_left_back_motor">
    <inertial>
      <mass value="0.05"/>
      <origin rpy="0  0  0" xyz="0     0    -0.012"/>
      <inertia ixx="1.2166047261762851e-05" ixy="0.0" ixz="0.0" iyy="1.4468363602365426e-05" iyz="0.0" izz="7.993829324731787e-06"/>
    </inertial>
    <collision name="aaly__thigh_left_back_motor_collision">
      <origin rpy="0  0  0" xyz="0  0  0"/>
      <geometry>
        <box size="0.04 0.032 0.050"/>
      </geometry>
    </collision>
    <visual name="aaly__thigh_left_back_motor_visual">
      <origin rpy="0  0  0" xyz="0  0  0"/>
      <geometry>
        <mesh filename="package://aaly_urdf/meshes/AX12-A_origin_same_as_center_of_mass.stl" scale="1.0 1.0 1.0"/>
      </geometry>
    </visual>
  </link>
  <link name="aaly__thigh_left_back">
    <inertial>
      <mass value="0.03"/>
      <origin rpy="0  0  0" xyz="0  0  0"/>
      <inertia ixx="2.0103848503359805e-05" ixy="0.0" ixz="0.0" iyy="1.2296884544899207e-05" iyz="0.0" izz="1.2205253512522909e-05"/>
    </inertial>
    <collision name="aaly__thigh_left_back_collision">
      <origin rpy="0  0  0" xyz="0     0     0.023"/>
      <geometry>
        <box size="0.04 0.032 0.030"/>
      </geometry>
    </collision>
    <visual name="aaly__thigh_left_back_visual">
      <origin rpy="0  0  0" xyz="0     0     0.023"/>
      <geometry>
        <mesh filename="package://aaly_urdf/meshes/Thigh.dae" scale="1.0 1.0 1.0"/>
      </geometry>
    </visual>
  </link>
  <link name="aaly__knee_left_front_motor">
    <inertial>
      <mass value="0.05"/>
      <origin rpy="0  0  0" xyz="0     0    -0.012"/>
      <inertia ixx="1.2166047261762851e-05" ixy="0.0" ixz="0.0" iyy="1.4468363602365426e-05" iyz="0.0" izz="7.993829324731787e-06"/>
    </inertial>
    <collision name="aaly__knee_left_front_motor_collision">
      <origin rpy="0  0  0" xyz="0  0  0"/>
      <geometry>
        <box size="0.04 0.032 0.050"/>
      </geometry>
    </collision>
    <visual name="aaly__knee_left_front_motor_visual">
      <origin rpy="0  0  0" xyz="0  0  0"/>
      <geometry>
        <mesh filename="package://aaly_urdf/meshes/AX12-A_origin_same_as_center_of_mass.stl" scale="1.0 1.0 1.0"/>
      </geometry>
    </visual>
  </link>
  <link name="aaly__leg_left_front">
    <inertial>
      <mass value="0.04"/>
      <origin rpy="0  0  0" xyz="0  0  0"/>
      <inertia ixx="2.69490184257131e-05" ixy="0.0" ixz="0.0" iyy="1.843324918045141e-05" iyz="0.0" izz="3.454538603564566e-05"/>
    </inertial>
    <collision name="aaly__leg_left_front_collision">
      <origin rpy="0  0  0" xyz="0  0  0"/>
      <geometry>
        <box size="0.04 0.04 0.025"/>
      </geometry>
    </collision>
    <visual name="aaly__leg_left_front_visual">
      <origin rpy="0  0  0" xyz="0  0  0"/>
      <geometry>
        <mesh filename="package://aaly_urdf/meshes/Leg_Left_Front.stl" scale="1.0 1.0 1.0"/>
      </geometry>
    </visual>
  </link>
  <link name="aaly__thigh_left_front_motor">
    <inertial>
      <mass value="0.05"/>
      <origin rpy="0  0  0" xyz="0     0    -0.012"/>
      <inertia ixx="1.2166047261762851e-05" ixy="0.0" ixz="0.0" iyy="1.4468363602365426e-05" iyz="0.0" izz="7.993829324731787e-06"/>
    </inertial>
    <collision name="aaly__thigh_left_front_motor_collision">
      <origin rpy="0  0  0" xyz="0  0  0"/>
      <geometry>
        <box size="0.04 0.032 0.050"/>
      </geometry>
    </collision>
    <visual name="aaly__thigh_left_front_motor_visual">
      <origin rpy="0  0  0" xyz="0  0  0"/>
      <geometry>
        <mesh filename="package://aaly_urdf/meshes/AX12-A_origin_same_as_center_of_mass.stl" scale="1.0 1.0 1.0"/>
      </geometry>
    </visual>
  </link>
  <link name="aaly__thigh_left_front">
    <inertial>
      <mass value="0.03"/>
      <origin rpy="0  0  0" xyz="0  0  0"/>
      <inertia ixx="2.0103848503359805e-05" ixy="0.0" ixz="0.0" iyy="1.2296884544899207e-05" iyz="0.0" izz="1.2205253512522909e-05"/>
    </inertial>
    <collision name="aaly__thigh_left_front_collision">
      <origin rpy="0  0  0" xyz="0     0     0.023"/>
      <geometry>
        <box size="0.04 0.032 0.030"/>
      </geometry>
    </collision>
    <visual name="aaly__thigh_left_front_visual">
      <origin rpy="0  0  0" xyz="0     0     0.023"/>
      <geometry>
        <mesh filename="package://aaly_urdf/meshes/Thigh.dae" scale="1.0 1.0 1.0"/>
      </geometry>
    </visual>
  </link>
  <link name="aaly__knee_right_back_motor">
    <inertial>
      <mass value="0.05"/>
      <origin rpy="0  0  0" xyz="0     0    -0.012"/>
      <inertia ixx="1.2166047261762851e-05" ixy="0.0" ixz="0.0" iyy="1.4468363602365426e-05" iyz="0.0" izz="7.993829324731787e-06"/>
    </inertial>
    <collision name="aaly__knee_right_back_motor_collision">
      <origin rpy="0  0  0" xyz="0  0  0"/>
      <geometry>
        <box size="0.04 0.032 0.050"/>
      </geometry>
    </collision>
    <visual name="aaly__knee_right_back_motor_visual">
      <origin rpy="0  0  0" xyz="0  0  0"/>
      <geometry>
        <mesh filename="package://aaly_urdf/meshes/AX12-A_origin_same_as_center_of_mass.stl" scale="1.0 1.0 1.0"/>
      </geometry>
    </visual>
  </link>
  <link name="aaly__leg_right_back">
    <inertial>
      <mass value="0.04"/>
      <origin rpy="0  0  0" xyz="0  0  0"/>
      <inertia ixx="2.69490184257131e-05" ixy="0.0" ixz="0.0" iyy="1.843324918045141e-05" iyz="0.0" izz="3.454538603564566e-05"/>
    </inertial>
    <collision name="aaly__leg_right_back_collision">
      <origin rpy="0  0  0" xyz="0  0  0"/>
      <geometry>
        <box size="0.04 0.04 0.025"/>
      </geometry>
    </collision>
    <visual name="aaly__leg_right_back_visual">
      <origin rpy="0  0  0" xyz="0  0  0"/>
      <geometry>
        <mesh filename="package://aaly_urdf/meshes/Leg_Right_Back.stl" scale="1.0 1.0 1.0"/>
      </geometry>
    </visual>
  </link>
  <link name="aaly__thigh_right_back_motor">
    <inertial>
      <mass value="0.05"/>
      <origin rpy="0  0  0" xyz="0     0    -0.012"/>
      <inertia ixx="1.2166047261762851e-05" ixy="0.0" ixz="0.0" iyy="1.4468363602365426e-05" iyz="0.0" izz="7.993829324731787e-06"/>
    </inertial>
    <collision name="aaly__thigh_right_back_motor_collision">
      <origin rpy="0  0  0" xyz="0  0  0"/>
      <geometry>
        <box size="0.04 0.032 0.050"/>
      </geometry>
    </collision>
    <visual name="aaly__thigh_right_back_motor_visual">
      <origin rpy="0  0  0" xyz="0  0  0"/>
      <geometry>
        <mesh filename="package://aaly_urdf/meshes/AX12-A_origin_same_as_center_of_mass.stl" scale="1.0 1.0 1.0"/>
      </geometry>
    </visual>
  </link>
  <link name="aaly__thigh_right_back">
    <inertial>
      <mass value="0.03"/>
      <origin rpy="0  0  0" xyz="0  0  0"/>
      <inertia ixx="2.0103848503359805e-05" ixy="0.0" ixz="0.0" iyy="1.2296884544899207e-05" iyz="0.0" izz="1.2205253512522909e-05"/>
    </inertial>
    <collision name="aaly__thigh_right_back_collision">
      <origin rpy="0.023  0     0" xyz="0  0  0"/>
      <geometry>
        <box size="0.04 0.032 0.030"/>
      </geometry>
    </collision>
    <visual name="aaly__thigh_right_back_visual">
      <origin rpy="0.023  0     0" xyz="0  0  0"/>
      <geometry>
        <mesh filename="package://aaly_urdf/meshes/Thigh.dae" scale="1.0 1.0 1.0"/>
      </geometry>
    </visual>
  </link>
  <link name="aaly__knee_right_front_motor">
    <inertial>
      <mass value="0.05"/>
      <origin rpy="0  0  0" xyz="0     0    -0.012"/>
      <inertia ixx="1.2166047261762851e-05" ixy="0.0" ixz="0.0" iyy="1.4468363602365426e-05" iyz="0.0" izz="7.993829324731787e-06"/>
    </inertial>
    <collision name="aaly__knee_right_front_motor_collision">
      <origin rpy="0  0  0" xyz="0  0  0"/>
      <geometry>
        <box size="0.04 0.032 0.050"/>
      </geometry>
    </collision>
    <visual name="aaly__knee_right_front_motor_visual">
      <origin rpy="0  0  0" xyz="0  0  0"/>
      <geometry>
        <mesh filename="package://aaly_urdf/meshes/AX12-A_origin_same_as_center_of_mass.stl" scale="1.0 1.0 1.0"/>
      </geometry>
    </visual>
  </link>
  <link name="aaly__leg_right_front">
    <inertial>
      <mass value="0.04"/>
      <origin rpy="0  0  0" xyz="0  0  0"/>
      <inertia ixx="2.69490184257131e-05" ixy="0.0" ixz="0.0" iyy="1.843324918045141e-05" iyz="0.0" izz="3.454538603564566e-05"/>
    </inertial>
    <collision name="aaly__leg_right_front_collision">
      <origin rpy="0  0  0" xyz="0  0  0"/>
      <geometry>
        <box size="0.04 0.04 0.025"/>
      </geometry>
    </collision>
    <visual name="aaly__leg_right_front_visual">
      <origin rpy="0  0  0" xyz="0  0  0"/>
      <geometry>
        <mesh filename="package://aaly_urdf/meshes/Leg_Right_Front.stl" scale="1.0 1.0 1.0"/>
      </geometry>
    </visual>
  </link>
  <link name="aaly__thigh_right_front_motor">
    <inertial>
      <mass value="0.05"/>
      <origin rpy="0  0  0" xyz="0     0    -0.012"/>
      <inertia ixx="1.2166047261762851e-05" ixy="0.0" ixz="0.0" iyy="1.4468363602365426e-05" iyz="0.0" izz="7.993829324731787e-06"/>
    </inertial>
    <collision name="aaly__thigh_right_front_motor_collision">
      <origin rpy="0  0  0" xyz="0  0  0"/>
      <geometry>
        <box size="0.04 0.032 0.050"/>
      </geometry>
    </collision>
    <visual name="aaly__thigh_right_front_motor_visual">
      <origin rpy="0  0  0" xyz="0  0  0"/>
      <geometry>
        <mesh filename="package://aaly_urdf/meshes/AX12-A_origin_same_as_center_of_mass.stl" scale="1.0 1.0 1.0"/>
      </geometry>
    </visual>
  </link>
  <link name="aaly__thigh_right_front">
    <inertial>
      <mass value="0.03"/>
      <origin rpy="0  0  0" xyz="0  0  0"/>
      <inertia ixx="2.0103848503359805e-05" ixy="0.0" ixz="0.0" iyy="1.2296884544899207e-05" iyz="0.0" izz="1.2205253512522909e-05"/>
    </inertial>
    <collision name="aaly__thigh_right_front_collision">
      <origin rpy="0  0  0" xyz="0     0     0.023"/>
      <geometry>
        <box size="0.04 0.032 0.030"/>
      </geometry>
    </collision>
    <visual name="aaly__thigh_right_front_visual">
      <origin rpy="0  0  0" xyz="0     0     0.023"/>
      <geometry>
        <mesh filename="package://aaly_urdf/meshes/Thigh.dae" scale="1.0 1.0 1.0"/>
      </geometry>
    </visual>
  </link>
  <link name="aaly__body1">
    <inertial>
      <mass value="0.05"/>
      <origin rpy="0  0  0" xyz="0  0  0"/>
      <inertia ixx="7.760416666666666e-05" ixy="0.0" ixz="0.0" iyy="8.041666666666667e-05" iyz="0.0" izz="3.802083333333334e-05"/>
    </inertial>
    <collision name="aaly__body1_collision">
      <origin rpy="0  0  0" xyz="0     0     0.065"/>
      <geometry>
        <box size="0.07 0.065 0.12"/>
      </geometry>
    </collision>
    <visual name="aaly__body1_visual">
      <origin rpy="0  0  0" xyz="0     0     0.065"/>
      <geometry>
        <box size="0.07 0.065 0.12"/>
      </geometry>
    </visual>
  </link>
  <link name="aaly__body2">
    <inertial>
      <mass value="0.05"/>
      <origin rpy="0  0  0" xyz="0  0  0"/>
      <inertia ixx="7.760416666666666e-05" ixy="0.0" ixz="0.0" iyy="8.041666666666667e-05" iyz="0.0" izz="3.802083333333334e-05"/>
    </inertial>
    <collision name="aaly__body2_collision">
      <origin rpy="0  0  0" xyz="-0.045  0     0"/>
      <geometry>
        <box size="0.07 0.065 0.12"/>
      </geometry>
    </collision>
    <visual name="aaly__body2_visual">
      <origin rpy="0  0  0" xyz="-0.045  0     0"/>
      <geometry>
        <box size="0.07 0.065 0.12"/>
      </geometry>
    </visual>
  </link>
  <link name="aaly__body3">
    <inertial>
      <mass value="0.05"/>
      <origin rpy="0  0  0" xyz="0  0  0"/>
      <inertia ixx="7.760416666666666e-05" ixy="0.0" ixz="0.0" iyy="8.041666666666667e-05" iyz="0.0" izz="3.802083333333334e-05"/>
    </inertial>
    <collision name="aaly__body1_collision">
      <origin rpy="0  0  0" xyz="0     0     0.065"/>
      <geometry>
        <box size="0.07 0.065 0.12"/>
      </geometry>
    </collision>
    <visual name="aaly__body1_visual">
      <origin rpy="0  0  0" xyz="0     0     0.065"/>
      <geometry>
        <box size="0.07 0.065 0.12"/>
      </geometry>
    </visual>
  </link>
  <link name="aaly__body4">
    <inertial>
      <mass value="0.05"/>
      <origin rpy="0  0  0" xyz="0  0  0"/>
      <inertia ixx="7.760416666666666e-05" ixy="0.0" ixz="0.0" iyy="8.041666666666667e-05" iyz="0.0" izz="3.802083333333334e-05"/>
    </inertial>
    <collision name="aaly__body2_collision">
      <origin rpy="0  0  0" xyz="-0.045  0     0"/>
      <geometry>
        <box size="0.07 0.065 0.12"/>
      </geometry>
    </collision>
    <visual name="aaly__body2_visual">
      <origin rpy="0  0  0" xyz="-0.045  0     0"/>
      <geometry>
        <box size="0.07 0.065 0.12"/>
      </geometry>
    </visual>
  </link>
  <link name="aaly__Right_Side_Track_Support">
    <inertial>
      <mass value="0.15"/>
      <origin rpy="0  0  0" xyz="0  0  0"/>
      <inertia ixx="0.00010520383183873306" ixy="-9.148702320585518e-07" ixz="3.7647066170409417e-05" iyy="0.00032229348287662684" iyz="2.722753728174257e-06" izz="0.0002182293357979667"/>
    </inertial>
    <collision name="aaly__Right_Side_Track_Support_collision">
      <origin rpy="0  0  0" xyz="0.05749 -0.004   -0.04273"/>
      <geometry>
        <mesh filename="package://aaly_urdf/meshes/Track_Support_Collision_Mesh.dae" scale="1.0 1.0 1.0"/>
      </geometry>
    </collision>
    <visual name="aaly__Right_Side_Track_Support_visual">
      <origin rpy="0  0  0" xyz="0.05749 -0.004   -0.05773"/>
      <geometry>
        <mesh filename="package://aaly_urdf/meshes/Track_Support_Left_Side.dae" scale="1.0 1.0 1.0"/>
      </geometry>
    </visual>
  </link>
  <link name="aaly__Left_Side_Track_Support">
    <inertial>
      <mass value="0.15"/>
      <origin rpy="0  0  0" xyz="0  0  0"/>
      <inertia ixx="0.00010520383183873306" ixy="-9.148702320585518e-07" ixz="3.7647066170409417e-05" iyy="0.00032229348287662684" iyz="2.722753728174257e-06" izz="0.0002182293357979667"/>
    </inertial>
    <collision name="aaly__Left_Side_Track_Support_collision">
      <origin rpy="0  0  0" xyz="0.05749  0.004   -0.04273"/>
      <geometry>
        <mesh filename="package://aaly_urdf/meshes/Track_Support_Collision_Mesh.dae" scale="1.0 1.0 1.0"/>
      </geometry>
    </collision>
    <visual name="aaly__Left_Side_Track_Support_visual">
      <origin rpy="0  0  0" xyz="0.05749  0.004   -0.05773"/>
      <geometry>
        <mesh filename="package://aaly_urdf/meshes/Track_Support_Right_Side.dae" scale="1.0 1.0 1.0"/>
      </geometry>
    </visual>
  </link>
  <link name="aaly__drum1">
    <inertial>
      <mass value="0.1"/>
      <origin rpy="0  0  0" xyz="0  0  0"/>
      <inertia ixx="2.787405275215884e-05" ixy="0.0" ixz="0.0" iyy="2.7903424778241207e-05" iyz="0.0" izz="1.7975679962403806e-05"/>
    </inertial>
    <collision name="aaly__drum1_collision">
      <origin rpy="0  0  0" xyz="0  0  0"/>
      <geometry>
        <cylinder length="0.05124" radius="0.026925"/>
      </geometry>
    </collision>
    <visual name="aaly__drum1_visual">
      <origin rpy="0  0  0" xyz="0  0  0"/>
      <geometry>
        <mesh filename="package://aaly_urdf/meshes/Lynx_Sproket6in_Hub13.dae" scale="1.0 1.0 1.0"/>
      </geometry>
    </visual>
  </link>
  <link name="aaly__drum2">
    <inertial>
      <mass value="0.1"/>
      <origin rpy="0  0  0" xyz="0  0  0"/>
      <inertia ixx="2.787405275215884e-05" ixy="0.0" ixz="0.0" iyy="2.7903424778241207e-05" iyz="0.0" izz="1.7975679962403806e-05"/>
    </inertial>
    <collision name="aaly__drum2_collision">
      <origin rpy="0  0  0" xyz="0  0  0"/>
      <geometry>
        <cylinder length="0.05124" radius="0.026925"/>
      </geometry>
    </collision>
    <visual name="aaly__drum2_visual">
      <origin rpy="0  0  0" xyz="0  0  0"/>
      <geometry>
        <mesh filename="package://aaly_urdf/meshes/Lynx_Sproket6in_Hub13.dae" scale="1.0 1.0 1.0"/>
      </geometry>
    </visual>
  </link>
  <link name="aaly__drum3">
    <inertial>
      <mass value="0.2"/>
      <origin rpy="0  0  0" xyz="0  0  0"/>
      <inertia ixx="0.00010790475895594018" ixy="0.0" ixz="0.0" iyy="0.00010774994581540083" iyz="0.0" izz="0.00012753506517633218"/>
    </inertial>
    <collision name="aaly__drum3_collision">
      <origin rpy="0  0  0" xyz="0  0  0"/>
      <geometry>
        <cylinder length="0.05124" radius="0.036625"/>
      </geometry>
    </collision>
    <visual name="aaly__drum3_visual">
      <origin rpy="0  0  0" xyz="0  0  0"/>
      <geometry>
        <mesh filename="package://aaly_urdf/meshes/Lynx_Sproket9in_Hub13.dae" scale="1.0 1.0 1.0"/>
      </geometry>
    </visual>
  </link>
  <link name="aaly__drum4">
    <inertial>
      <mass value="0.2"/>
      <origin rpy="0  0  0" xyz="0  0  0"/>
      <inertia ixx="0.00010790475895594018" ixy="0.0" ixz="0.0" iyy="0.00010774994581540083" iyz="0.0" izz="0.00012753506517633218"/>
    </inertial>
    <collision name="aaly__drum4_collision">
      <origin rpy="0  0  0" xyz="0  0  0"/>
      <geometry>
        <cylinder length="0.05124" radius="0.036625"/>
      </geometry>
    </collision>
    <visual name="aaly__drum4_visual">
      <origin rpy="0  0  0" xyz="0  0  0"/>
      <geometry>
        <mesh filename="package://aaly_urdf/meshes/Lynx_Sproket9in_Hub13.dae" scale="1.0 1.0 1.0"/>
      </geometry>
    </visual>
  </link>
  <link name="aaly__drum5">
    <inertial>
      <mass value="0.1"/>
      <origin rpy="0  0  0" xyz="0  0  0"/>
      <inertia ixx="2.787405275215884e-05" ixy="0.0" ixz="0.0" iyy="2.7903424778241207e-05" iyz="0.0" izz="1.7975679962403806e-05"/>
    </inertial>
    <collision name="aaly__drum5_collision">
      <origin rpy="0  0  0" xyz="0  0  0"/>
      <geometry>
        <cylinder length="0.05124" radius="0.027025"/>
      </geometry>
    </collision>
    <visual name="aaly__drum5_visual">
      <origin rpy="0  0  0" xyz="0  0  0"/>
      <geometry>
        <mesh filename="package://aaly_urdf/meshes/Lynx_Sproket6in_Hub13.dae" scale="1.0 1.0 1.0"/>
      </geometry>
    </visual>
  </link>
  <link name="aaly__drum6">
    <inertial>
      <mass value="0.1"/>
      <origin rpy="0  0  0" xyz="0  0  0"/>
      <inertia ixx="2.787405275215884e-05" ixy="0.0" ixz="0.0" iyy="2.7903424778241207e-05" iyz="0.0" izz="1.7975679962403806e-05"/>
    </inertial>
    <collision name="aaly__drum6_collision">
      <origin rpy="0  0  0" xyz="0  0  0"/>
      <geometry>
        <cylinder length="0.05124" radius="0.027025"/>
      </geometry>
    </collision>
    <visual name="aaly__drum6_visual">
      <origin rpy="0  0  0" xyz="0  0  0"/>
      <geometry>
        <mesh filename="package://aaly_urdf/meshes/Lynx_Sproket6in_Hub13.dae" scale="1.0 1.0 1.0"/>
      </geometry>
    </visual>
  </link>
  <link name="aaly__Right_Side_Track_Cover">
    <inertial>
      <mass value="0.15"/>
      <origin rpy="0  0  0" xyz="0  0  0"/>
      <inertia ixx="0.00010520383183873306" ixy="-9.148702320585518e-07" ixz="3.7647066170409417e-05" iyy="0.00032229348287662684" iyz="2.722753728174257e-06" izz="0.0002182293357979667"/>
    </inertial>
    <collision name="aaly__Right_Side_Track_Cover_collision">
      <origin rpy="0  0  0" xyz="0     0     0.015"/>
      <geometry>
        <mesh filename="package://aaly_urdf/meshes/Track_Support_Collision_Mesh.dae" scale="1.0 1.0 1.0"/>
      </geometry>
    </collision>
    <visual name="aaly__Right_Side_Track_Cover_visual">
      <origin rpy="0  0  0" xyz="0  0  0"/>
      <geometry>
        <mesh filename="package://aaly_urdf/meshes/Track_Support_Cover_Side.dae" scale="1.0 1.0 1.0"/>
      </geometry>
    </visual>
  </link>
  <link name="aaly__Left_Side_Track_Cover">
    <inertial>
      <mass value="0.15"/>
      <origin rpy="0  0  0" xyz="0  0  0"/>
      <inertia ixx="0.00010520383183873306" ixy="-9.148702320585518e-07" ixz="3.7647066170409417e-05" iyy="0.00032229348287662684" iyz="2.722753728174257e-06" izz="0.0002182293357979667"/>
    </inertial>
    <collision name="aaly__Left_Side_Track_Cover_collision">
      <origin rpy="0  0  0" xyz="0     0     0.015"/>
      <geometry>
        <mesh filename="package://aaly_urdf/meshes/Track_Support_Collision_Mesh.dae" scale="1.0 1.0 1.0"/>
      </geometry>
    </collision>
    <visual name="aaly__Left_Side_Track_Cover_visual">
      <origin rpy="0  0  0" xyz="0  0  0"/>
      <geometry>
        <mesh filename="package://aaly_urdf/meshes/Track_Support_Cover_Side.dae" scale="1.0 1.0 1.0"/>
      </geometry>
    </visual>
  </link>



  <transmission name="tran1">
    <type>transmission_interface/SimpleTransmission</type>
    <joint name="aaly__knee_left_back_joint">
      <hardwareInterface>hardware_interface/PositionJointInterface</hardwareInterface>
    </joint>
    <actuator name="aaly__knee_left_back_motor">
      <hardwareInterface>hardware_interface/PositionJointInterface</hardwareInterface>
      <mechanicalReduction>1</mechanicalReduction>
    </actuator>
  </transmission>

  <transmission name="tran2">
    <type>transmission_interface/SimpleTransmission</type>
    <joint name="aaly__knee_left_front_joint">
      <hardwareInterface>hardware_interface/PositionJointInterface</hardwareInterface>
    </joint>
    <actuator name="aaly__knee_left_front_motor">
      <hardwareInterface>hardware_interface/PositionJointInterface</hardwareInterface>
      <mechanicalReduction>1</mechanicalReduction>
    </actuator>
  </transmission>

  <transmission name="tran3">
    <type>transmission_interface/SimpleTransmission</type>
    <joint name="aaly__knee_right_back_joint">
      <hardwareInterface>hardware_interface/PositionJointInterface</hardwareInterface>
    </joint>
    <actuator name="aaly__knee_right_back_motor">
      <hardwareInterface>hardware_interface/PositionJointInterface</hardwareInterface>
      <mechanicalReduction>1</mechanicalReduction>
    </actuator>
  </transmission>

  <transmission name="tran4">
    <type>transmission_interface/SimpleTransmission</type>
    <joint name="aaly__knee_right_front_joint">
      <hardwareInterface>hardware_interface/PositionJointInterface</hardwareInterface>
    </joint>
    <actuator name="aaly__knee_right_front_motor">
      <hardwareInterface>hardware_interface/PositionJointInterface</hardwareInterface>
      <mechanicalReduction>1</mechanicalReduction>
    </actuator>
  </transmission>
  <transmission name="tran5">
    <type>transmission_interface/SimpleTransmission</type>
    <joint name="aaly__thigh_left_back_motor_joint">
      <hardwareInterface>hardware_interface/PositionJointInterface</hardwareInterface>
    </joint>
    <actuator name="aaly__thigh_left_back_motor">
      <hardwareInterface>hardware_interface/PositionJointInterface</hardwareInterface>
      <mechanicalReduction>1</mechanicalReduction>
    </actuator>
  </transmission>

  <transmission name="tran6">
    <type>transmission_interface/SimpleTransmission</type>
    <joint name="aaly__thigh_left_front_motor_joint">
      <hardwareInterface>hardware_interface/PositionJointInterface</hardwareInterface>
    </joint>
    <actuator name="aaly__thigh_left_front_motor">
      <hardwareInterface>hardware_interface/PositionJointInterface</hardwareInterface>
      <mechanicalReduction>1</mechanicalReduction>
    </actuator>
  </transmission>

  <transmission name="tran7">
    <type>transmission_interface/SimpleTransmission</type>
    <joint name="aaly__thigh_right_back_motor_joint">
      <hardwareInterface>hardware_interface/PositionJointInterface</hardwareInterface>
    </joint>
    <actuator name="aaly__thigh_right_back_motor">
      <hardwareInterface>hardware_interface/PositionJointInterface</hardwareInterface>
      <mechanicalReduction>1</mechanicalReduction>
    </actuator>
  </transmission>

  <transmission name="tran8">
    <type>transmission_interface/SimpleTransmission</type>
    <joint name="aaly__thigh_right_front_motor_joint">
      <hardwareInterface>hardware_interface/PositionJointInterface</hardwareInterface>
    </joint>
    <actuator name="aaly__thigh_right_front_motor">
      <hardwareInterface>hardware_interface/PositionJointInterface</hardwareInterface>
      <mechanicalReduction>1</mechanicalReduction>
    </actuator>
  </transmission>

  <transmission name="tran9">
    <type>transmission_interface/SimpleTransmission</type>
    <joint name="aaly__body_front_right_joint">
      <hardwareInterface>hardware_interface/PositionJointInterface</hardwareInterface>
    </joint>
    <actuator name="body_front_right_joint">
      <hardwareInterface>hardware_interface/PositionJointInterface</hardwareInterface>
      <mechanicalReduction>1</mechanicalReduction>
    </actuator>
  </transmission>

  <transmission name="tran10">
    <type>transmission_interface/SimpleTransmission</type>
    <joint name="aaly__body_back_right_joint">
      <hardwareInterface>hardware_interface/PositionJointInterface</hardwareInterface>
    </joint>
    <actuator name="body_back_right_joint">
      <hardwareInterface>hardware_interface/PositionJointInterface</hardwareInterface>
      <mechanicalReduction>1</mechanicalReduction>
    </actuator>
  </transmission>

  <transmission name="tran11">
    <type>transmission_interface/SimpleTransmission</type>
    <joint name="aaly__body_front_left_joint">
      <hardwareInterface>hardware_interface/PositionJointInterface</hardwareInterface>
    </joint>
    <actuator name="body_front_left_joint">
      <hardwareInterface>hardware_interface/PositionJointInterface</hardwareInterface>
      <mechanicalReduction>1</mechanicalReduction>
    </actuator>
  </transmission>

  <transmission name="tran12">
    <type>transmission_interface/SimpleTransmission</type>
    <joint name="aaly__body_back_left_joint">
      <hardwareInterface>hardware_interface/PositionJointInterface</hardwareInterface>
    </joint>
    <actuator name="body_back_left_joint">
      <hardwareInterface>hardware_interface/PositionJointInterface</hardwareInterface>
      <mechanicalReduction>1</mechanicalReduction>
    </actuator>
  </transmission>

</robot>
